{"summary":"---\n## instruction:\nThe errors are caused by a `ModuleNotFoundError` for the `fastapi` module, which indicates that the `fastapi` package is not installed in the environment where the tests are being run. This is not directly related to the logic or structure of the test or development code itself, but rather to the environment setup. To correct this issue, ensure that the `fastapi` package is installed in the active Python environment. You can do this by running `pip install fastapi` in the terminal or including `fastapi` in your project's requirements.txt file and installing from there. Additionally, ensure that all other dependencies are correctly installed and accessible in the test environment.\n\n## File To Rewrite:\nNo specific file needs to be rewritten to fix the error directly. However, reviewing and updating the environment setup or requirements.txt file may be necessary.\n\n## Status:\nFAIL\n\n## Send To:\nQaEngineer\n\n---","stdout":"","stderr":"EEEEE\n======================================================================\nERROR: test_base_declarative (__main__.TestDatabaseSession)\nTest if Base is an instance of the declarative base.\n----------------------------------------------------------------------\nTraceback (most recent call last):\n  File \"/Users/laptop/miniconda3/envs/mg/lib/python3.9/unittest/mock.py\", line 1333, in patched\n    with self.decoration_helper(patched,\n  File \"/Users/laptop/miniconda3/envs/mg/lib/python3.9/contextlib.py\", line 119, in __enter__\n    return next(self.gen)\n  File \"/Users/laptop/miniconda3/envs/mg/lib/python3.9/unittest/mock.py\", line 1315, in decoration_helper\n    arg = exit_stack.enter_context(patching)\n  File \"/Users/laptop/miniconda3/envs/mg/lib/python3.9/contextlib.py\", line 448, in enter_context\n    result = _cm_type.__enter__(cm)\n  File \"/Users/laptop/miniconda3/envs/mg/lib/python3.9/unittest/mock.py\", line 1388, in __enter__\n    self.target = self.getter()\n  File \"/Users/laptop/miniconda3/envs/mg/lib/python3.9/unittest/mock.py\", line 1563, in <lambda>\n    getter = lambda: _importer(target)\n  File \"/Users/laptop/miniconda3/envs/mg/lib/python3.9/unittest/mock.py\", line 1235, in _importer\n    thing = __import__(import_path)\n  File \"/Users/laptop/MetaGPT/workspace/async_fastapi_nlp_agent_system/async_fastapi_nlp_agent_system/app/__init__.py\", line 1, in <module>\n    from fastapi import FastAPI, Depends\nModuleNotFoundError: No module named 'fastapi'\n\n======================================================================\nERROR: test_engine_url (__main__.TestDatabaseSession)\nTest if the engine URL matches the DATABASE_URL from settings.\n----------------------------------------------------------------------\nTraceback (most recent call last):\n  File \"/Users/laptop/miniconda3/envs/mg/lib/python3.9/unittest/mock.py\", line 1333, in patched\n    with self.decoration_helper(patched,\n  File \"/Users/laptop/miniconda3/envs/mg/lib/python3.9/contextlib.py\", line 119, in __enter__\n    return next(self.gen)\n  File \"/Users/laptop/miniconda3/envs/mg/lib/python3.9/unittest/mock.py\", line 1315, in decoration_helper\n    arg = exit_stack.enter_context(patching)\n  File \"/Users/laptop/miniconda3/envs/mg/lib/python3.9/contextlib.py\", line 448, in enter_context\n    result = _cm_type.__enter__(cm)\n  File \"/Users/laptop/miniconda3/envs/mg/lib/python3.9/unittest/mock.py\", line 1388, in __enter__\n    self.target = self.getter()\n  File \"/Users/laptop/miniconda3/envs/mg/lib/python3.9/unittest/mock.py\", line 1563, in <lambda>\n    getter = lambda: _importer(target)\n  File \"/Users/laptop/miniconda3/envs/mg/lib/python3.9/unittest/mock.py\", line 1235, in _importer\n    thing = __import__(import_path)\n  File \"/Users/laptop/MetaGPT/workspace/async_fastapi_nlp_agent_system/async_fastapi_nlp_agent_system/app/__init__.py\", line 1, in <module>\n    from fastapi import FastAPI, Depends\nModuleNotFoundError: No module named 'fastapi'\n\n======================================================================\nERROR: test_get_db_yield_type (__main__.TestDatabaseSession)\nTest if get_db yields a SQLAlchemy Session.\n----------------------------------------------------------------------\nTraceback (most recent call last):\n  File \"/Users/laptop/miniconda3/envs/mg/lib/python3.9/unittest/mock.py\", line 1333, in patched\n    with self.decoration_helper(patched,\n  File \"/Users/laptop/miniconda3/envs/mg/lib/python3.9/contextlib.py\", line 119, in __enter__\n    return next(self.gen)\n  File \"/Users/laptop/miniconda3/envs/mg/lib/python3.9/unittest/mock.py\", line 1315, in decoration_helper\n    arg = exit_stack.enter_context(patching)\n  File \"/Users/laptop/miniconda3/envs/mg/lib/python3.9/contextlib.py\", line 448, in enter_context\n    result = _cm_type.__enter__(cm)\n  File \"/Users/laptop/miniconda3/envs/mg/lib/python3.9/unittest/mock.py\", line 1388, in __enter__\n    self.target = self.getter()\n  File \"/Users/laptop/miniconda3/envs/mg/lib/python3.9/unittest/mock.py\", line 1563, in <lambda>\n    getter = lambda: _importer(target)\n  File \"/Users/laptop/miniconda3/envs/mg/lib/python3.9/unittest/mock.py\", line 1235, in _importer\n    thing = __import__(import_path)\n  File \"/Users/laptop/MetaGPT/workspace/async_fastapi_nlp_agent_system/async_fastapi_nlp_agent_system/app/__init__.py\", line 1, in <module>\n    from fastapi import FastAPI, Depends\nModuleNotFoundError: No module named 'fastapi'\n\n======================================================================\nERROR: test_session_local_type (__main__.TestDatabaseSession)\nTest if SessionLocal is an instance of sessionmaker.\n----------------------------------------------------------------------\nTraceback (most recent call last):\n  File \"/Users/laptop/miniconda3/envs/mg/lib/python3.9/unittest/mock.py\", line 1333, in patched\n    with self.decoration_helper(patched,\n  File \"/Users/laptop/miniconda3/envs/mg/lib/python3.9/contextlib.py\", line 119, in __enter__\n    return next(self.gen)\n  File \"/Users/laptop/miniconda3/envs/mg/lib/python3.9/unittest/mock.py\", line 1315, in decoration_helper\n    arg = exit_stack.enter_context(patching)\n  File \"/Users/laptop/miniconda3/envs/mg/lib/python3.9/contextlib.py\", line 448, in enter_context\n    result = _cm_type.__enter__(cm)\n  File \"/Users/laptop/miniconda3/envs/mg/lib/python3.9/unittest/mock.py\", line 1388, in __enter__\n    self.target = self.getter()\n  File \"/Users/laptop/miniconda3/envs/mg/lib/python3.9/unittest/mock.py\", line 1563, in <lambda>\n    getter = lambda: _importer(target)\n  File \"/Users/laptop/miniconda3/envs/mg/lib/python3.9/unittest/mock.py\", line 1235, in _importer\n    thing = __import__(import_path)\n  File \"/Users/laptop/MetaGPT/workspace/async_fastapi_nlp_agent_system/async_fastapi_nlp_agent_system/app/__init__.py\", line 1, in <module>\n    from fastapi import FastAPI, Depends\nModuleNotFoundError: No module named 'fastapi'\n\n======================================================================\nERROR: test_sqlite_connect_args (__main__.TestDatabaseSession)\nTest if connect_args is correctly set for SQLite.\n----------------------------------------------------------------------\nTraceback (most recent call last):\n  File \"/Users/laptop/miniconda3/envs/mg/lib/python3.9/unittest/mock.py\", line 1333, in patched\n    with self.decoration_helper(patched,\n  File \"/Users/laptop/miniconda3/envs/mg/lib/python3.9/contextlib.py\", line 119, in __enter__\n    return next(self.gen)\n  File \"/Users/laptop/miniconda3/envs/mg/lib/python3.9/unittest/mock.py\", line 1315, in decoration_helper\n    arg = exit_stack.enter_context(patching)\n  File \"/Users/laptop/miniconda3/envs/mg/lib/python3.9/contextlib.py\", line 448, in enter_context\n    result = _cm_type.__enter__(cm)\n  File \"/Users/laptop/miniconda3/envs/mg/lib/python3.9/unittest/mock.py\", line 1388, in __enter__\n    self.target = self.getter()\n  File \"/Users/laptop/miniconda3/envs/mg/lib/python3.9/unittest/mock.py\", line 1563, in <lambda>\n    getter = lambda: _importer(target)\n  File \"/Users/laptop/miniconda3/envs/mg/lib/python3.9/unittest/mock.py\", line 1235, in _importer\n    thing = __import__(import_path)\n  File \"/Users/laptop/MetaGPT/workspace/async_fastapi_nlp_agent_system/async_fastapi_nlp_agent_system/app/__init__.py\", line 1, in <module>\n    from fastapi import FastAPI, Depends\nModuleNotFoundError: No module named 'fastapi'\n\n----------------------------------------------------------------------\nRan 5 tests in 0.002s\n\nFAILED (errors=5)\n"}