{"summary":"---\n## instruction:\nThe error is caused by an ImportError in the development code, specifically in the initialization of the app where it tries to import various modules from 'app.api.v1.endpoints' which either do not exist or are not accessible in the specified location. To correct this error, ensure that all the modules ('agents', 'roles', 'influences', 'stages', 'groups', 'tasks', 'news', 'recommendations', 'training', 'feedback') are correctly implemented and accessible in 'app.api.v1.endpoints'. If these modules are supposed to be mocked for the test, ensure the mocking is correctly set up before the import statement that fails. If the modules indeed exist, verify the PYTHONPATH or the project structure to ensure the import statement can correctly locate the modules.\n## File To Rewrite:\napp/__init__.py\n## Status:\nFAIL\n## Send To:\nEngineer\n---","stdout":"","stderr":"Traceback (most recent call last):\n  File \"/Users/laptop/MetaGPT/workspace/async_fastapi_nlp_agent_system/tests/test_app/core/dependencies.py\", line 29, in <module>\n    from app.core.dependencies import get_db\n  File \"/Users/laptop/MetaGPT/workspace/async_fastapi_nlp_agent_system/async_fastapi_nlp_agent_system/app/__init__.py\", line 2, in <module>\n    from app.api.v1.endpoints import agents, roles, influences, stages, groups, tasks, news, recommendations, training, feedback\nImportError: cannot import name 'agents' from 'app.api.v1.endpoints' (unknown location)\n"}