{"summary":"---\n## instruction:\nThe errors are caused by a `ModuleNotFoundError` for `fastapi`, indicating that the `fastapi` module is not installed in the environment where the tests are being run. This error is not directly related to the logic of the development code or the test code but is an environment setup issue. To correct this, ensure that `fastapi` is installed in the test environment. You can do this by running `pip install fastapi` in your terminal or including `fastapi` in your project's requirements.txt file and installing from there.\n\n## File To Rewrite:\nNo specific file needs to be rewritten to fix the error. However, ensuring the test environment is correctly set up is crucial.\n\n## Status:\nFAIL\n\n## Send To:\nQaEngineer\n\n---","stdout":"","stderr":"EEE..\n======================================================================\nERROR: test_file_logging_configuration (__main__.TestConfigureLogging)\nTest that file logging is configured correctly when enabled.\n----------------------------------------------------------------------\nTraceback (most recent call last):\n  File \"/Users/laptop/miniconda3/envs/mg/lib/python3.9/unittest/mock.py\", line 1333, in patched\n    with self.decoration_helper(patched,\n  File \"/Users/laptop/miniconda3/envs/mg/lib/python3.9/contextlib.py\", line 119, in __enter__\n    return next(self.gen)\n  File \"/Users/laptop/miniconda3/envs/mg/lib/python3.9/unittest/mock.py\", line 1315, in decoration_helper\n    arg = exit_stack.enter_context(patching)\n  File \"/Users/laptop/miniconda3/envs/mg/lib/python3.9/contextlib.py\", line 448, in enter_context\n    result = _cm_type.__enter__(cm)\n  File \"/Users/laptop/miniconda3/envs/mg/lib/python3.9/unittest/mock.py\", line 1388, in __enter__\n    self.target = self.getter()\n  File \"/Users/laptop/miniconda3/envs/mg/lib/python3.9/unittest/mock.py\", line 1563, in <lambda>\n    getter = lambda: _importer(target)\n  File \"/Users/laptop/miniconda3/envs/mg/lib/python3.9/unittest/mock.py\", line 1235, in _importer\n    thing = __import__(import_path)\n  File \"/Users/laptop/MetaGPT/workspace/async_fastapi_nlp_agent_system/async_fastapi_nlp_agent_system/app/__init__.py\", line 1, in <module>\n    from fastapi import FastAPI, Depends\nModuleNotFoundError: No module named 'fastapi'\n\n======================================================================\nERROR: test_log_level_set_correctly (__main__.TestConfigureLogging)\nTest that the log level is set correctly in the logger.\n----------------------------------------------------------------------\nTraceback (most recent call last):\n  File \"/Users/laptop/miniconda3/envs/mg/lib/python3.9/unittest/mock.py\", line 1333, in patched\n    with self.decoration_helper(patched,\n  File \"/Users/laptop/miniconda3/envs/mg/lib/python3.9/contextlib.py\", line 119, in __enter__\n    return next(self.gen)\n  File \"/Users/laptop/miniconda3/envs/mg/lib/python3.9/unittest/mock.py\", line 1315, in decoration_helper\n    arg = exit_stack.enter_context(patching)\n  File \"/Users/laptop/miniconda3/envs/mg/lib/python3.9/contextlib.py\", line 448, in enter_context\n    result = _cm_type.__enter__(cm)\n  File \"/Users/laptop/miniconda3/envs/mg/lib/python3.9/unittest/mock.py\", line 1388, in __enter__\n    self.target = self.getter()\n  File \"/Users/laptop/miniconda3/envs/mg/lib/python3.9/unittest/mock.py\", line 1563, in <lambda>\n    getter = lambda: _importer(target)\n  File \"/Users/laptop/miniconda3/envs/mg/lib/python3.9/unittest/mock.py\", line 1235, in _importer\n    thing = __import__(import_path)\n  File \"/Users/laptop/MetaGPT/workspace/async_fastapi_nlp_agent_system/async_fastapi_nlp_agent_system/app/__init__.py\", line 1, in <module>\n    from fastapi import FastAPI, Depends\nModuleNotFoundError: No module named 'fastapi'\n\n======================================================================\nERROR: test_logging_configuration (__main__.TestConfigureLogging)\nTest that logging is configured correctly based on LoggerConfig settings.\n----------------------------------------------------------------------\nTraceback (most recent call last):\n  File \"/Users/laptop/miniconda3/envs/mg/lib/python3.9/unittest/mock.py\", line 1333, in patched\n    with self.decoration_helper(patched,\n  File \"/Users/laptop/miniconda3/envs/mg/lib/python3.9/contextlib.py\", line 119, in __enter__\n    return next(self.gen)\n  File \"/Users/laptop/miniconda3/envs/mg/lib/python3.9/unittest/mock.py\", line 1315, in decoration_helper\n    arg = exit_stack.enter_context(patching)\n  File \"/Users/laptop/miniconda3/envs/mg/lib/python3.9/contextlib.py\", line 448, in enter_context\n    result = _cm_type.__enter__(cm)\n  File \"/Users/laptop/miniconda3/envs/mg/lib/python3.9/unittest/mock.py\", line 1388, in __enter__\n    self.target = self.getter()\n  File \"/Users/laptop/miniconda3/envs/mg/lib/python3.9/unittest/mock.py\", line 1563, in <lambda>\n    getter = lambda: _importer(target)\n  File \"/Users/laptop/miniconda3/envs/mg/lib/python3.9/unittest/mock.py\", line 1235, in _importer\n    thing = __import__(import_path)\n  File \"/Users/laptop/MetaGPT/workspace/async_fastapi_nlp_agent_system/async_fastapi_nlp_agent_system/app/__init__.py\", line 1, in <module>\n    from fastapi import FastAPI, Depends\nModuleNotFoundError: No module named 'fastapi'\n\n----------------------------------------------------------------------\nRan 5 tests in 0.003s\n\nFAILED (errors=3)\n"}